Workbook

Sheet Parametros a actualizar
B2: PARÁMETROS DE LA SEMANA — actualizar acá, no en las hojas de modelos
B3: Fecha de actualización | C3: 46254 | D3: Sólo modificar los campos con texto azul
B5: 1. Macro y financiero
B7: Inflación esperada mensual | C7: 0.0175 | D7: Fermín: promedio 1,7-1,8%. REM jul-26 (public. 6/8): mediana 2,0% mensual puntual. Próx. REM: 4/9. https://www.bcra.gob.ar/relevamiento-expectativas-mercado-rem/ | E7: https://www.bcra.gob.ar/relevamiento-expectativas-mercado-rem/
B8: Tasa de plazo fijo (TNA) | C8: 0.19 | D8: Actualizar según tasa vigente al momento de correr el modelo. | E8: https://www.bcra.gob.ar/plazos-fijos-online/
B9: Tasa efectiva mensual PF (referencia) | C9: =(1+C8)^(1/12)-1 | D9: Se calcula sola a partir de la TNA de arriba.
B10: Tasa anual costo financiero (si hay que pedir plata) | C10: 0.25 | D10: Mismo dato que el archivo viejo (00 Sistemas de Engorde).
B12: 2. Dólar
B14: Dólar hoy (inicio) | C14: 1515 | D14: Actualizar con cotización vigente.
B15: Dólar proyectado dic-26 (REM, referencia) | C15: 1652 | D15: REM jul-26, mediana para dic-26 ($1.652/USD). | E15: https://www.bcra.gob.ar/relevamiento-expectativas-mercado-rem/
B17: 3. Precios de hacienda — históricos y de mercado hoy
B18: Fecha de compra | C18: 46113
B19: Ternero 180 kg — precio pagado en abril (histórico) | C19: 6600 | D19: Precio real pagado en abril-2026. Fuente: Entre Surcos y Corrales (invernada). NO es el precio de hoy — es el dato histórico de la compra.
B20: Meses transcurridos desde la compra (abril → hoy) | C20: =(C3-C18)/30 | D20: Se calcula solo, a partir de la fecha de actualización de arriba y la fecha de compra (abril).
B21: Ternero 180 kg — actualizado a pesos de hoy | C21: =C19*(1+C7)^C20 | D21: Precio de abril llevado a pesos de hoy con la inflación esperada mensual. Este es el valor que debe usar el modelo como costo de compra en términos reales — no el precio histórico sin actualizar. | E21: La fórmula =(1+TNA)^(1/12)-1 asume interés compuesto mensual. Un plazo fijo real a 30 días no capitaliza dentro del mes — es simple: TNA/12. La diferencia es chica a estos plazos, pero cuando lo uso para proyectar 5-7 meses hacia adelante (fila 69, =(1+TNA)^(meses/12)) sí importa
E22: Al precio de compra lo llevo hacia adelante con inflación esperada (capitalizando). Al precio de venta futuro lo traigo hacia atrás con la misma tasa (descontando)
B23: Novillito/recriado ~270 kg — precio de mercado HOY | C23: 6200 | D23: Entre Surcos y Corrales (invernada) — precio vigente de la semana. Ya está en pesos de hoy, no requiere actualización.
B24: Novillo gordo 415-440 kg — precio de mercado HOY | C24: 4600 | D24: Mercado Agroganadero de Cañuelas (consumo/gordo) — precio vigente de la semana.
B25: Novillo gordo exportación ~500 kg — precio de mercado HOY | C25: 4600 | D25: Mercado Agroganadero de Cañuelas, categoría exportación — precio vigente de la semana.
B27: 4. Gastos comerciales (%)
B29: % Gastos comerciales — compra | C29: 0.05
B30: % Gastos comerciales — venta | C30: 0.07
B32: 5. Capitalización — sobre kg ganados
B34: % para el dueño del animal | C34: 0.45 | D34: reparto sobre kilos ganados, no sobre valor.
B35: % para el engordador (capitalizador) | C35: =1-C34
B38: 6. SITUACION ACTUAL — ¿Dónde estamos?
B40: ¿Cuál camino eligió al inicio? | C40: 1 | D40: (1=Venta oct, 2=Cap, 3=Corral, 4=Pastura, 5=Recría+corral)
B41: Fecha de hoy | C41: =TODAY()
B42: Margen acumulado hasta hoy | C42: 0

Sheet Modelos
C2: MODELOS RECRÍA + ENGORDE 2026 — Ternero 180 kg (abril) → 5 caminos desde octubre
G3: 1 | H3: 2 | I3: 3 | J3: 4 | K3: 5
C4: CAMINOS (desde 270 kg, oct-2026) | G4: Venta oct. + plazo fijo | H4: Capitalización (mar) | I4: Corral liviano (feb-jun) | J4: Engorde a pastura (mar) | K4: Recría+corral propio (may)
G5: Vende en octubre a 270 kg; compara contra poner esa plata a plazo fijo. | H5: Envía a capitalizar: sale gordo en marzo 430-440 kg. Reparto 45% dueño / 55% engordador sobre kilos ganados. | I5: Entra a corral de inicio liviano a ppios de febrero: 270→415 kg, 120 días, 1,2 kg/d. | J5: Engorde a pastura propio: sale en marzo con 430-440 kg. | K5: Recría en pastura hasta febrero (400 kg) + 90 días de corral propio a 1,1 kg/d, sale en mayo con 500 kg.
C6: Categoría inicial | E6: Ternero 180 kg
C7: Fecha de compra | E7: 46113
C8: Peso inicial (compra) | D8: kg | E8: 180
C9: Precio de compra (actualizado a pesos de hoy) | D9: $/kg | E9: ='Parametros a actualizar'!$C$21
C10: % Gastos comerciales - compra | E10: ='Parametros a actualizar'!$C$29
C12: ADPV etapa (verdeo invierno) | D12: kg/d | E12: 0.7
C13: Peso a la salida (1/oct) | D13: kg | E13: 270
C14: Fecha de salida (llegada a 270 kg) | E14: 46296
C15: Duración etapa | D15: días | E15: =E14-E7
C16: Kg producidos etapa | D16: kg/cab | E16: =E13-E8
C18: Nota | E18: Ritmo de recría según lo cargado por Fermín en sus notas (verdeo de invierno). Ver también variante 0,5 kg/d si se quiere comparar.
C20: Costo de compra neto (con gastos comerciales) | D20: $/cab | E20: =E8*E9*(1+E10)
C21: Valor del animal a la salida de la etapa común | D21: kg a 270 kg
C22: (referencia — cada camino valúa este punto de partida con su propio precio de ingreso)
C24: 1. FICHA TÉCNICA
C25: Peso entrada (= salida etapa común) | D25: kg | G25: =$E$13 | H25: =$E$13 | I25: =$E$13 | J25: =$E$13 | K25: =$E$13
C26: Fecha entrada (= salida etapa común) | G26: =$E$14 | H26: =$E$14 | I26: =$E$14 | J26: =$E$14 | K26: =$E$14
C27: Peso de salida (venta) | D27: kg | G27: 270 | H27: 435 | I27: 415 | J27: 435 | K27: 500
C28: ADPV del camino | D28: kg/d | H28: 0.55 | I28: 1.2 | J28: 0.6
C29: Fecha de salida (venta) | G29: 46296 | H29: 46447 | I29: 46419 | J29: 46447 | K29: 46508
C30: Duración del camino (desde oct) | D30: días | G30: =G29-G26 | H30: =H29-H26 | I30: =I29-I26 | J30: =J29-J26 | K30: =K29-K26
C31: Kg producidos en el camino | D31: kg/cab | G31: =G27-G25 | H31: =H27-H25 | I31: =I27-I25 | J31: =J27-J25 | K31: =K27-K25
C32: % Mortandad del camino | D32: % | G32: 0 | H32: 0.01 | I32: 0.02 | J32: 0.01 | K32: 0.015
C34: 2. PRECIOS (deflactados a pesos de hoy — inflación esperada + dólar)
C35: Precio de ingreso (270 kg, oct) — pesos de hoy | D35: $/kg | G35: ='Parametros a actualizar'!$C$23 | H35: ='Parametros a actualizar'!$C$23 | I35: ='Parametros a actualizar'!$C$23 | J35: ='Parametros a actualizar'!$C$23 | K35: ='Parametros a actualizar'!$C$23
C36: Precio de venta esperado (nominal, a la fecha de salida) | D36: $/kg | G36: ='Parametros a actualizar'!$C$23 | H36: ='Parametros a actualizar'!$C$24 | I36: ='Parametros a actualizar'!$C$24 | J36: ='Parametros a actualizar'!$C$24 | K36: ='Parametros a actualizar'!$C$25
C37: Meses entre entrada y venta (para deflactar) | D37: meses | G37: =(G29-G26)/30 | H37: =(H29-H26)/30 | I37: =(I29-I26)/30 | J37: =(J29-J26)/30 | K37: =(K29-K26)/30
C38: Precio de venta deflactado a pesos de hoy | D38: $/kg | G38: =G36/(1+'Parametros a actualizar'!$C$7)^G37 | H38: =H36/(1+'Parametros a actualizar'!$C$7)^H37 | I38: =I36/(1+'Parametros a actualizar'!$C$7)^I37 | J38: =J36/(1+'Parametros a actualizar'!$C$7)^J37 | K38: =K36/(1+'Parametros a actualizar'!$C$7)^K37
C40: Camino 1 no necesita deflactar (venta el mismo día de la etapa común). Los demás traen el precio de venta futuro a pesos de hoy con la inflación esperada de Parámetros (1,7-1,8% mensual, definido por Fermín).
C42: 3. INGRESOS Y GASTOS (pesos de hoy)
C43: Ingreso bruto por venta [Camino 2: (kg entrada + 45% kg ganados) x precio venta] | D43: $/cab | G43: =G27*G38*(1-G32) | H43: =(H25+(H31*'Parametros a actualizar'!$C$34))*H38*(1-H32) | I43: =I27*I38*(1-I32) | J43: =J27*J38*(1-J32) | K43: =K27*K38*(1-K32)
C44: % Gastos comerciales - venta | D44: % | G44: ='Parametros a actualizar'!$C$30 | H44: ='Parametros a actualizar'!$C$30 | I44: ='Parametros a actualizar'!$C$30 | J44: ='Parametros a actualizar'!$C$30 | K44: ='Parametros a actualizar'!$C$30
C45: Ingreso neto de venta | D45: $/cab | G45: =G43*(1-G44) | H45: =H43*(1-H44) | I45: =I43*(1-I44) | J45: =J43*(1-J44) | K45: =K43*(1-K44)
C47: 4. COSTOS DEL CAMINO (desde oct, además del costo de compra ya incorporado en la etapa común)
C48: Costo de alimentación / recría / corral | D48: $/cab | G48: =G31*G104 | H48: =H31*H104 | I48: =I31*I104 | J48: =J31*J104 | K48: =K31*K104
C49: Sanidad | D49: $/cab | E49: 0.02 | G49: =$E$9*$E$49 | H49: =$E$9*$E$49 | I49: =$E$9*$E$49 | J49: =$E$9*$E$49 | K49: =$E$9*$E$49
...
